<robot
  name="knife_description">
  <link name="knife_base"/>
  <link
    name="knife_link">
    <inertial>
      <origin
        xyz="0 0 0"
        rpy="0 0 0" />
      <mass
        value="0.47626" />
      <inertia
        ixx="0"
        ixy="0"
        ixz="0"
        iyy="0"
        iyz="0"
        izz="0" />
    </inertial>
    <visual>
      <origin
        xyz="0 0 0"
        rpy="0 0 0" />
      <geometry>
        <mesh
          filename="package://knife/meshes/knife.stl" />
      </geometry>
      <material
        name="">
        <color
          rgba="0.79216 0.81961 0.93333 1" />
      </material>
    </visual>
    <collision>
      <origin
        xyz="0 0 0"
        rpy="0 0 0" />
      <geometry>
        <mesh
          filename="package://knife/meshes/knife.stl" />
      </geometry>
    </collision>
  </link>
  <joint name="joint_knife" type="floating">
    <origin xyz="0 0 0" rpy="0 0 0"/>
    <parent link="knife_base"/>
    <child link="knife_link"/>
  </joint>
</robot>
